2023-12-13 12:50:12,581 ERROR scheduler Exception in Enqueue Events for Site NEW_INDIA
Traceback (most recent call last):
  File "env/lib/python3.10/site-packages/rq/job.py", line 552, in restore
    raw_data = obj['data']
KeyError: 'data'

During handling of the above exception, another exception occurred:

Traceback (most recent call last):
  File "apps/frappe/frappe/utils/scheduler.py", line 78, in enqueue_events_for_site
    enqueue_events(site=site)
  File "apps/frappe/frappe/utils/scheduler.py", line 96, in enqueue_events
    queued_jobs = get_jobs(site=site, key="job_type").get(site) or []
  File "apps/frappe/frappe/utils/background_jobs.py", line 305, in get_jobs
    jobs = q.jobs + get_running_jobs_in_queue(q)
  File "apps/frappe/frappe/utils/background_jobs.py", line 344, in get_running_jobs_in_queue
    current_job = worker.get_current_job()
  File "env/lib/python3.10/site-packages/rq/worker.py", line 421, in get_current_job
    return self.job_class.fetch(job_id, self.connection, self.serializer)
  File "env/lib/python3.10/site-packages/rq/job.py", line 372, in fetch
    job.refresh()
  File "env/lib/python3.10/site-packages/rq/job.py", line 618, in refresh
    self.restore(data)
  File "env/lib/python3.10/site-packages/rq/job.py", line 554, in restore
    raise NoSuchJobError('Unexpected job format: {0}'.format(obj))
rq.exceptions.NoSuchJobError: Unexpected job format: {'last_heartbeat': b'2023-12-13T07:20:12.567052Z', 'status': b'started', 'started_at': b'2023-12-13T07:20:12.567052Z', 'worker_name': b'38fb589c804946bbba9b77f9e82c21ff'}

2023-12-26 10:17:58,444 ERROR scheduler Exception in Enqueue Events for Site NEW_INDIA
Traceback (most recent call last):
  File "apps/frappe/frappe/utils/scheduler.py", line 78, in enqueue_events_for_site
    enqueue_events(site=site)
  File "apps/frappe/frappe/utils/scheduler.py", line 96, in enqueue_events
    queued_jobs = get_jobs(site=site, key="job_type").get(site) or []
  File "apps/frappe/frappe/utils/background_jobs.py", line 304, in get_jobs
    q = get_queue(_queue)
  File "apps/frappe/frappe/utils/background_jobs.py", line 353, in get_queue
    return Queue(generate_qname(qtype), connection=get_redis_conn(), is_async=is_async)
  File "env/lib/python3.10/site-packages/tenacity/__init__.py", line 324, in wrapped_f
    return self(f, *args, **kw)
  File "env/lib/python3.10/site-packages/tenacity/__init__.py", line 404, in __call__
    do = self.iter(retry_state=retry_state)
  File "env/lib/python3.10/site-packages/tenacity/__init__.py", line 349, in iter
    return fut.result()
  File "/usr/lib/python3.10/concurrent/futures/_base.py", line 451, in result
    return self.__get_result()
  File "/usr/lib/python3.10/concurrent/futures/_base.py", line 403, in __get_result
    raise self._exception
  File "env/lib/python3.10/site-packages/tenacity/__init__.py", line 407, in __call__
    result = fn(*args, **kwargs)
  File "apps/frappe/frappe/utils/background_jobs.py", line 374, in get_redis_conn
    raise Exception("redis_queue missing in common_site_config.json")
Exception: redis_queue missing in common_site_config.json

2023-12-26 10:18:58,558 ERROR scheduler Exception in Enqueue Events for Site NEW_INDIA
Traceback (most recent call last):
  File "apps/frappe/frappe/utils/scheduler.py", line 78, in enqueue_events_for_site
    enqueue_events(site=site)
  File "apps/frappe/frappe/utils/scheduler.py", line 96, in enqueue_events
    queued_jobs = get_jobs(site=site, key="job_type").get(site) or []
  File "apps/frappe/frappe/utils/background_jobs.py", line 304, in get_jobs
    q = get_queue(_queue)
  File "apps/frappe/frappe/utils/background_jobs.py", line 353, in get_queue
    return Queue(generate_qname(qtype), connection=get_redis_conn(), is_async=is_async)
  File "env/lib/python3.10/site-packages/tenacity/__init__.py", line 324, in wrapped_f
    return self(f, *args, **kw)
  File "env/lib/python3.10/site-packages/tenacity/__init__.py", line 404, in __call__
    do = self.iter(retry_state=retry_state)
  File "env/lib/python3.10/site-packages/tenacity/__init__.py", line 349, in iter
    return fut.result()
  File "/usr/lib/python3.10/concurrent/futures/_base.py", line 451, in result
    return self.__get_result()
  File "/usr/lib/python3.10/concurrent/futures/_base.py", line 403, in __get_result
    raise self._exception
  File "env/lib/python3.10/site-packages/tenacity/__init__.py", line 407, in __call__
    result = fn(*args, **kwargs)
  File "apps/frappe/frappe/utils/background_jobs.py", line 374, in get_redis_conn
    raise Exception("redis_queue missing in common_site_config.json")
Exception: redis_queue missing in common_site_config.json

2023-12-26 10:19:58,671 ERROR scheduler Exception in Enqueue Events for Site NEW_INDIA
Traceback (most recent call last):
  File "apps/frappe/frappe/utils/scheduler.py", line 78, in enqueue_events_for_site
    enqueue_events(site=site)
  File "apps/frappe/frappe/utils/scheduler.py", line 96, in enqueue_events
    queued_jobs = get_jobs(site=site, key="job_type").get(site) or []
  File "apps/frappe/frappe/utils/background_jobs.py", line 304, in get_jobs
    q = get_queue(_queue)
  File "apps/frappe/frappe/utils/background_jobs.py", line 353, in get_queue
    return Queue(generate_qname(qtype), connection=get_redis_conn(), is_async=is_async)
  File "env/lib/python3.10/site-packages/tenacity/__init__.py", line 324, in wrapped_f
    return self(f, *args, **kw)
  File "env/lib/python3.10/site-packages/tenacity/__init__.py", line 404, in __call__
    do = self.iter(retry_state=retry_state)
  File "env/lib/python3.10/site-packages/tenacity/__init__.py", line 349, in iter
    return fut.result()
  File "/usr/lib/python3.10/concurrent/futures/_base.py", line 451, in result
    return self.__get_result()
  File "/usr/lib/python3.10/concurrent/futures/_base.py", line 403, in __get_result
    raise self._exception
  File "env/lib/python3.10/site-packages/tenacity/__init__.py", line 407, in __call__
    result = fn(*args, **kwargs)
  File "apps/frappe/frappe/utils/background_jobs.py", line 374, in get_redis_conn
    raise Exception("redis_queue missing in common_site_config.json")
Exception: redis_queue missing in common_site_config.json

2024-01-10 16:35:32,358 ERROR scheduler Exception in Enqueue Events for Site NEW_INDIA
Traceback (most recent call last):
  File "apps/frappe/frappe/utils/scheduler.py", line 75, in enqueue_events_for_site
    if is_scheduler_inactive():
  File "apps/frappe/frappe/utils/scheduler.py", line 114, in is_scheduler_inactive
    if is_scheduler_disabled(verbose=verbose):
  File "apps/frappe/frappe/utils/scheduler.py", line 127, in is_scheduler_disabled
    frappe.db.get_single_value("System Settings", "enable_scheduler")
  File "apps/frappe/frappe/database/database.py", line 786, in get_single_value
    ).run()
  File "apps/frappe/frappe/query_builder/utils.py", line 87, in execute_query
    result = frappe.db.sql(query, params, *args, **kwargs)  # nosemgrep
  File "apps/frappe/frappe/database/database.py", line 220, in sql
    self._cursor.execute(query, values)
  File "env/lib/python3.10/site-packages/pymysql/cursors.py", line 158, in execute
    result = self._query(query)
  File "env/lib/python3.10/site-packages/pymysql/cursors.py", line 325, in _query
    conn.query(q)
  File "env/lib/python3.10/site-packages/pymysql/connections.py", line 549, in query
    self._affected_rows = self._read_query_result(unbuffered=unbuffered)
  File "env/lib/python3.10/site-packages/pymysql/connections.py", line 779, in _read_query_result
    result.read()
  File "env/lib/python3.10/site-packages/pymysql/connections.py", line 1157, in read
    first_packet = self.connection._read_packet()
  File "env/lib/python3.10/site-packages/pymysql/connections.py", line 729, in _read_packet
    packet.raise_for_error()
  File "env/lib/python3.10/site-packages/pymysql/protocol.py", line 221, in raise_for_error
    err.raise_mysql_exception(self._data)
  File "env/lib/python3.10/site-packages/pymysql/err.py", line 143, in raise_mysql_exception
    raise errorclass(errno, errval)
pymysql.err.ProgrammingError: (1146, "Table '_1fb9db47a8d26d78.tabSingles' doesn't exist")

2024-01-10 16:36:32,463 ERROR scheduler Exception in Enqueue Events for Site NEW_INDIA
Traceback (most recent call last):
  File "apps/frappe/frappe/utils/scheduler.py", line 75, in enqueue_events_for_site
    if is_scheduler_inactive():
  File "apps/frappe/frappe/utils/scheduler.py", line 114, in is_scheduler_inactive
    if is_scheduler_disabled(verbose=verbose):
  File "apps/frappe/frappe/utils/scheduler.py", line 127, in is_scheduler_disabled
    frappe.db.get_single_value("System Settings", "enable_scheduler")
  File "apps/frappe/frappe/database/database.py", line 786, in get_single_value
    ).run()
  File "apps/frappe/frappe/query_builder/utils.py", line 87, in execute_query
    result = frappe.db.sql(query, params, *args, **kwargs)  # nosemgrep
  File "apps/frappe/frappe/database/database.py", line 220, in sql
    self._cursor.execute(query, values)
  File "env/lib/python3.10/site-packages/pymysql/cursors.py", line 158, in execute
    result = self._query(query)
  File "env/lib/python3.10/site-packages/pymysql/cursors.py", line 325, in _query
    conn.query(q)
  File "env/lib/python3.10/site-packages/pymysql/connections.py", line 549, in query
    self._affected_rows = self._read_query_result(unbuffered=unbuffered)
  File "env/lib/python3.10/site-packages/pymysql/connections.py", line 779, in _read_query_result
    result.read()
  File "env/lib/python3.10/site-packages/pymysql/connections.py", line 1157, in read
    first_packet = self.connection._read_packet()
  File "env/lib/python3.10/site-packages/pymysql/connections.py", line 729, in _read_packet
    packet.raise_for_error()
  File "env/lib/python3.10/site-packages/pymysql/protocol.py", line 221, in raise_for_error
    err.raise_mysql_exception(self._data)
  File "env/lib/python3.10/site-packages/pymysql/err.py", line 143, in raise_mysql_exception
    raise errorclass(errno, errval)
pymysql.err.ProgrammingError: (1146, "Table '_1fb9db47a8d26d78.tabSingles' doesn't exist")

2024-01-10 16:38:53,867 ERROR scheduler Exception in Enqueue Events for Site NEW_INDIA
Traceback (most recent call last):
  File "apps/frappe/frappe/utils/scheduler.py", line 75, in enqueue_events_for_site
    if is_scheduler_inactive():
  File "apps/frappe/frappe/utils/scheduler.py", line 114, in is_scheduler_inactive
    if is_scheduler_disabled(verbose=verbose):
  File "apps/frappe/frappe/utils/scheduler.py", line 127, in is_scheduler_disabled
    frappe.db.get_single_value("System Settings", "enable_scheduler")
  File "apps/frappe/frappe/database/database.py", line 786, in get_single_value
    ).run()
  File "apps/frappe/frappe/query_builder/utils.py", line 87, in execute_query
    result = frappe.db.sql(query, params, *args, **kwargs)  # nosemgrep
  File "apps/frappe/frappe/database/database.py", line 220, in sql
    self._cursor.execute(query, values)
  File "env/lib/python3.10/site-packages/pymysql/cursors.py", line 158, in execute
    result = self._query(query)
  File "env/lib/python3.10/site-packages/pymysql/cursors.py", line 325, in _query
    conn.query(q)
  File "env/lib/python3.10/site-packages/pymysql/connections.py", line 549, in query
    self._affected_rows = self._read_query_result(unbuffered=unbuffered)
  File "env/lib/python3.10/site-packages/pymysql/connections.py", line 779, in _read_query_result
    result.read()
  File "env/lib/python3.10/site-packages/pymysql/connections.py", line 1157, in read
    first_packet = self.connection._read_packet()
  File "env/lib/python3.10/site-packages/pymysql/connections.py", line 729, in _read_packet
    packet.raise_for_error()
  File "env/lib/python3.10/site-packages/pymysql/protocol.py", line 221, in raise_for_error
    err.raise_mysql_exception(self._data)
  File "env/lib/python3.10/site-packages/pymysql/err.py", line 143, in raise_mysql_exception
    raise errorclass(errno, errval)
pymysql.err.ProgrammingError: (1146, "Table '_1fb9db47a8d26d78.tabSingles' doesn't exist")

2024-01-10 16:39:54,203 ERROR scheduler Exception in Enqueue Events for Site NEW_INDIA
Traceback (most recent call last):
  File "apps/frappe/frappe/utils/scheduler.py", line 75, in enqueue_events_for_site
    if is_scheduler_inactive():
  File "apps/frappe/frappe/utils/scheduler.py", line 114, in is_scheduler_inactive
    if is_scheduler_disabled(verbose=verbose):
  File "apps/frappe/frappe/utils/scheduler.py", line 127, in is_scheduler_disabled
    frappe.db.get_single_value("System Settings", "enable_scheduler")
  File "apps/frappe/frappe/database/database.py", line 786, in get_single_value
    ).run()
  File "apps/frappe/frappe/query_builder/utils.py", line 87, in execute_query
    result = frappe.db.sql(query, params, *args, **kwargs)  # nosemgrep
  File "apps/frappe/frappe/database/database.py", line 220, in sql
    self._cursor.execute(query, values)
  File "env/lib/python3.10/site-packages/pymysql/cursors.py", line 158, in execute
    result = self._query(query)
  File "env/lib/python3.10/site-packages/pymysql/cursors.py", line 325, in _query
    conn.query(q)
  File "env/lib/python3.10/site-packages/pymysql/connections.py", line 549, in query
    self._affected_rows = self._read_query_result(unbuffered=unbuffered)
  File "env/lib/python3.10/site-packages/pymysql/connections.py", line 779, in _read_query_result
    result.read()
  File "env/lib/python3.10/site-packages/pymysql/connections.py", line 1157, in read
    first_packet = self.connection._read_packet()
  File "env/lib/python3.10/site-packages/pymysql/connections.py", line 729, in _read_packet
    packet.raise_for_error()
  File "env/lib/python3.10/site-packages/pymysql/protocol.py", line 221, in raise_for_error
    err.raise_mysql_exception(self._data)
  File "env/lib/python3.10/site-packages/pymysql/err.py", line 143, in raise_mysql_exception
    raise errorclass(errno, errval)
pymysql.err.ProgrammingError: (1146, "Table '_1fb9db47a8d26d78.tabSingles' doesn't exist")

2024-01-10 16:44:38,565 ERROR scheduler Exception in Enqueue Events for Site NEW_INDIA
Traceback (most recent call last):
  File "apps/frappe/frappe/utils/scheduler.py", line 75, in enqueue_events_for_site
    if is_scheduler_inactive():
  File "apps/frappe/frappe/utils/scheduler.py", line 114, in is_scheduler_inactive
    if is_scheduler_disabled(verbose=verbose):
  File "apps/frappe/frappe/utils/scheduler.py", line 127, in is_scheduler_disabled
    frappe.db.get_single_value("System Settings", "enable_scheduler")
  File "apps/frappe/frappe/database/database.py", line 786, in get_single_value
    ).run()
  File "apps/frappe/frappe/query_builder/utils.py", line 87, in execute_query
    result = frappe.db.sql(query, params, *args, **kwargs)  # nosemgrep
  File "apps/frappe/frappe/database/database.py", line 220, in sql
    self._cursor.execute(query, values)
  File "env/lib/python3.10/site-packages/pymysql/cursors.py", line 158, in execute
    result = self._query(query)
  File "env/lib/python3.10/site-packages/pymysql/cursors.py", line 325, in _query
    conn.query(q)
  File "env/lib/python3.10/site-packages/pymysql/connections.py", line 549, in query
    self._affected_rows = self._read_query_result(unbuffered=unbuffered)
  File "env/lib/python3.10/site-packages/pymysql/connections.py", line 779, in _read_query_result
    result.read()
  File "env/lib/python3.10/site-packages/pymysql/connections.py", line 1157, in read
    first_packet = self.connection._read_packet()
  File "env/lib/python3.10/site-packages/pymysql/connections.py", line 729, in _read_packet
    packet.raise_for_error()
  File "env/lib/python3.10/site-packages/pymysql/protocol.py", line 221, in raise_for_error
    err.raise_mysql_exception(self._data)
  File "env/lib/python3.10/site-packages/pymysql/err.py", line 143, in raise_mysql_exception
    raise errorclass(errno, errval)
pymysql.err.ProgrammingError: (1146, "Table '_1fb9db47a8d26d78.tabSingles' doesn't exist")

2024-01-10 16:45:38,833 ERROR scheduler Exception in Enqueue Events for Site NEW_INDIA
Traceback (most recent call last):
  File "apps/frappe/frappe/utils/scheduler.py", line 75, in enqueue_events_for_site
    if is_scheduler_inactive():
  File "apps/frappe/frappe/utils/scheduler.py", line 114, in is_scheduler_inactive
    if is_scheduler_disabled(verbose=verbose):
  File "apps/frappe/frappe/utils/scheduler.py", line 127, in is_scheduler_disabled
    frappe.db.get_single_value("System Settings", "enable_scheduler")
  File "apps/frappe/frappe/database/database.py", line 786, in get_single_value
    ).run()
  File "apps/frappe/frappe/query_builder/utils.py", line 87, in execute_query
    result = frappe.db.sql(query, params, *args, **kwargs)  # nosemgrep
  File "apps/frappe/frappe/database/database.py", line 220, in sql
    self._cursor.execute(query, values)
  File "env/lib/python3.10/site-packages/pymysql/cursors.py", line 158, in execute
    result = self._query(query)
  File "env/lib/python3.10/site-packages/pymysql/cursors.py", line 325, in _query
    conn.query(q)
  File "env/lib/python3.10/site-packages/pymysql/connections.py", line 549, in query
    self._affected_rows = self._read_query_result(unbuffered=unbuffered)
  File "env/lib/python3.10/site-packages/pymysql/connections.py", line 779, in _read_query_result
    result.read()
  File "env/lib/python3.10/site-packages/pymysql/connections.py", line 1157, in read
    first_packet = self.connection._read_packet()
  File "env/lib/python3.10/site-packages/pymysql/connections.py", line 729, in _read_packet
    packet.raise_for_error()
  File "env/lib/python3.10/site-packages/pymysql/protocol.py", line 221, in raise_for_error
    err.raise_mysql_exception(self._data)
  File "env/lib/python3.10/site-packages/pymysql/err.py", line 143, in raise_mysql_exception
    raise errorclass(errno, errval)
pymysql.err.ProgrammingError: (1146, "Table '_1fb9db47a8d26d78.tabSingles' doesn't exist")

2024-01-10 16:49:17,918 ERROR scheduler Exception in Enqueue Events for Site NEW_INDIA
Traceback (most recent call last):
  File "apps/frappe/frappe/utils/scheduler.py", line 75, in enqueue_events_for_site
    if is_scheduler_inactive():
  File "apps/frappe/frappe/utils/scheduler.py", line 114, in is_scheduler_inactive
    if is_scheduler_disabled(verbose=verbose):
  File "apps/frappe/frappe/utils/scheduler.py", line 127, in is_scheduler_disabled
    frappe.db.get_single_value("System Settings", "enable_scheduler")
  File "apps/frappe/frappe/database/database.py", line 786, in get_single_value
    ).run()
  File "apps/frappe/frappe/query_builder/utils.py", line 87, in execute_query
    result = frappe.db.sql(query, params, *args, **kwargs)  # nosemgrep
  File "apps/frappe/frappe/database/database.py", line 220, in sql
    self._cursor.execute(query, values)
  File "env/lib/python3.10/site-packages/pymysql/cursors.py", line 158, in execute
    result = self._query(query)
  File "env/lib/python3.10/site-packages/pymysql/cursors.py", line 325, in _query
    conn.query(q)
  File "env/lib/python3.10/site-packages/pymysql/connections.py", line 549, in query
    self._affected_rows = self._read_query_result(unbuffered=unbuffered)
  File "env/lib/python3.10/site-packages/pymysql/connections.py", line 779, in _read_query_result
    result.read()
  File "env/lib/python3.10/site-packages/pymysql/connections.py", line 1157, in read
    first_packet = self.connection._read_packet()
  File "env/lib/python3.10/site-packages/pymysql/connections.py", line 729, in _read_packet
    packet.raise_for_error()
  File "env/lib/python3.10/site-packages/pymysql/protocol.py", line 221, in raise_for_error
    err.raise_mysql_exception(self._data)
  File "env/lib/python3.10/site-packages/pymysql/err.py", line 143, in raise_mysql_exception
    raise errorclass(errno, errval)
pymysql.err.ProgrammingError: (1146, "Table '_1fb9db47a8d26d78.tabSingles' doesn't exist")

2024-01-10 16:51:06,271 ERROR scheduler Exception in Enqueue Events for Site NEW_INDIA
Traceback (most recent call last):
  File "apps/frappe/frappe/utils/scheduler.py", line 75, in enqueue_events_for_site
    if is_scheduler_inactive():
  File "apps/frappe/frappe/utils/scheduler.py", line 114, in is_scheduler_inactive
    if is_scheduler_disabled(verbose=verbose):
  File "apps/frappe/frappe/utils/scheduler.py", line 127, in is_scheduler_disabled
    frappe.db.get_single_value("System Settings", "enable_scheduler")
  File "apps/frappe/frappe/database/database.py", line 786, in get_single_value
    ).run()
  File "apps/frappe/frappe/query_builder/utils.py", line 87, in execute_query
    result = frappe.db.sql(query, params, *args, **kwargs)  # nosemgrep
  File "apps/frappe/frappe/database/database.py", line 220, in sql
    self._cursor.execute(query, values)
  File "env/lib/python3.10/site-packages/pymysql/cursors.py", line 158, in execute
    result = self._query(query)
  File "env/lib/python3.10/site-packages/pymysql/cursors.py", line 325, in _query
    conn.query(q)
  File "env/lib/python3.10/site-packages/pymysql/connections.py", line 549, in query
    self._affected_rows = self._read_query_result(unbuffered=unbuffered)
  File "env/lib/python3.10/site-packages/pymysql/connections.py", line 779, in _read_query_result
    result.read()
  File "env/lib/python3.10/site-packages/pymysql/connections.py", line 1157, in read
    first_packet = self.connection._read_packet()
  File "env/lib/python3.10/site-packages/pymysql/connections.py", line 729, in _read_packet
    packet.raise_for_error()
  File "env/lib/python3.10/site-packages/pymysql/protocol.py", line 221, in raise_for_error
    err.raise_mysql_exception(self._data)
  File "env/lib/python3.10/site-packages/pymysql/err.py", line 143, in raise_mysql_exception
    raise errorclass(errno, errval)
pymysql.err.ProgrammingError: (1146, "Table '_1fb9db47a8d26d78.tabSingles' doesn't exist")

2024-01-10 17:01:54,759 ERROR scheduler Exception in Enqueue Events for Site NEW_INDIA
Traceback (most recent call last):
  File "apps/frappe/frappe/utils/scheduler.py", line 75, in enqueue_events_for_site
    if is_scheduler_inactive():
  File "apps/frappe/frappe/utils/scheduler.py", line 114, in is_scheduler_inactive
    if is_scheduler_disabled(verbose=verbose):
  File "apps/frappe/frappe/utils/scheduler.py", line 127, in is_scheduler_disabled
    frappe.db.get_single_value("System Settings", "enable_scheduler")
  File "apps/frappe/frappe/database/database.py", line 786, in get_single_value
    ).run()
  File "apps/frappe/frappe/query_builder/utils.py", line 87, in execute_query
    result = frappe.db.sql(query, params, *args, **kwargs)  # nosemgrep
  File "apps/frappe/frappe/database/database.py", line 220, in sql
    self._cursor.execute(query, values)
  File "env/lib/python3.10/site-packages/pymysql/cursors.py", line 158, in execute
    result = self._query(query)
  File "env/lib/python3.10/site-packages/pymysql/cursors.py", line 325, in _query
    conn.query(q)
  File "env/lib/python3.10/site-packages/pymysql/connections.py", line 549, in query
    self._affected_rows = self._read_query_result(unbuffered=unbuffered)
  File "env/lib/python3.10/site-packages/pymysql/connections.py", line 779, in _read_query_result
    result.read()
  File "env/lib/python3.10/site-packages/pymysql/connections.py", line 1157, in read
    first_packet = self.connection._read_packet()
  File "env/lib/python3.10/site-packages/pymysql/connections.py", line 729, in _read_packet
    packet.raise_for_error()
  File "env/lib/python3.10/site-packages/pymysql/protocol.py", line 221, in raise_for_error
    err.raise_mysql_exception(self._data)
  File "env/lib/python3.10/site-packages/pymysql/err.py", line 143, in raise_mysql_exception
    raise errorclass(errno, errval)
pymysql.err.ProgrammingError: (1146, "Table '_1fb9db47a8d26d78.tabSingles' doesn't exist")

2024-01-10 17:02:55,117 ERROR scheduler Exception in Enqueue Events for Site NEW_INDIA
Traceback (most recent call last):
  File "apps/frappe/frappe/utils/scheduler.py", line 75, in enqueue_events_for_site
    if is_scheduler_inactive():
  File "apps/frappe/frappe/utils/scheduler.py", line 114, in is_scheduler_inactive
    if is_scheduler_disabled(verbose=verbose):
  File "apps/frappe/frappe/utils/scheduler.py", line 127, in is_scheduler_disabled
    frappe.db.get_single_value("System Settings", "enable_scheduler")
  File "apps/frappe/frappe/database/database.py", line 786, in get_single_value
    ).run()
  File "apps/frappe/frappe/query_builder/utils.py", line 87, in execute_query
    result = frappe.db.sql(query, params, *args, **kwargs)  # nosemgrep
  File "apps/frappe/frappe/database/database.py", line 220, in sql
    self._cursor.execute(query, values)
  File "env/lib/python3.10/site-packages/pymysql/cursors.py", line 158, in execute
    result = self._query(query)
  File "env/lib/python3.10/site-packages/pymysql/cursors.py", line 325, in _query
    conn.query(q)
  File "env/lib/python3.10/site-packages/pymysql/connections.py", line 549, in query
    self._affected_rows = self._read_query_result(unbuffered=unbuffered)
  File "env/lib/python3.10/site-packages/pymysql/connections.py", line 779, in _read_query_result
    result.read()
  File "env/lib/python3.10/site-packages/pymysql/connections.py", line 1157, in read
    first_packet = self.connection._read_packet()
  File "env/lib/python3.10/site-packages/pymysql/connections.py", line 729, in _read_packet
    packet.raise_for_error()
  File "env/lib/python3.10/site-packages/pymysql/protocol.py", line 221, in raise_for_error
    err.raise_mysql_exception(self._data)
  File "env/lib/python3.10/site-packages/pymysql/err.py", line 143, in raise_mysql_exception
    raise errorclass(errno, errval)
pymysql.err.ProgrammingError: (1146, "Table '_1fb9db47a8d26d78.tabSingles' doesn't exist")

2024-01-10 17:03:55,348 ERROR scheduler Exception in Enqueue Events for Site NEW_INDIA
Traceback (most recent call last):
  File "apps/frappe/frappe/utils/scheduler.py", line 75, in enqueue_events_for_site
    if is_scheduler_inactive():
  File "apps/frappe/frappe/utils/scheduler.py", line 114, in is_scheduler_inactive
    if is_scheduler_disabled(verbose=verbose):
  File "apps/frappe/frappe/utils/scheduler.py", line 127, in is_scheduler_disabled
    frappe.db.get_single_value("System Settings", "enable_scheduler")
  File "apps/frappe/frappe/database/database.py", line 786, in get_single_value
    ).run()
  File "apps/frappe/frappe/query_builder/utils.py", line 87, in execute_query
    result = frappe.db.sql(query, params, *args, **kwargs)  # nosemgrep
  File "apps/frappe/frappe/database/database.py", line 220, in sql
    self._cursor.execute(query, values)
  File "env/lib/python3.10/site-packages/pymysql/cursors.py", line 158, in execute
    result = self._query(query)
  File "env/lib/python3.10/site-packages/pymysql/cursors.py", line 325, in _query
    conn.query(q)
  File "env/lib/python3.10/site-packages/pymysql/connections.py", line 549, in query
    self._affected_rows = self._read_query_result(unbuffered=unbuffered)
  File "env/lib/python3.10/site-packages/pymysql/connections.py", line 779, in _read_query_result
    result.read()
  File "env/lib/python3.10/site-packages/pymysql/connections.py", line 1157, in read
    first_packet = self.connection._read_packet()
  File "env/lib/python3.10/site-packages/pymysql/connections.py", line 729, in _read_packet
    packet.raise_for_error()
  File "env/lib/python3.10/site-packages/pymysql/protocol.py", line 221, in raise_for_error
    err.raise_mysql_exception(self._data)
  File "env/lib/python3.10/site-packages/pymysql/err.py", line 143, in raise_mysql_exception
    raise errorclass(errno, errval)
pymysql.err.ProgrammingError: (1146, "Table '_1fb9db47a8d26d78.tabSingles' doesn't exist")

2024-01-10 17:04:55,872 ERROR scheduler Exception in Enqueue Events for Site NEW_INDIA
Traceback (most recent call last):
  File "apps/frappe/frappe/utils/scheduler.py", line 75, in enqueue_events_for_site
    if is_scheduler_inactive():
  File "apps/frappe/frappe/utils/scheduler.py", line 114, in is_scheduler_inactive
    if is_scheduler_disabled(verbose=verbose):
  File "apps/frappe/frappe/utils/scheduler.py", line 127, in is_scheduler_disabled
    frappe.db.get_single_value("System Settings", "enable_scheduler")
  File "apps/frappe/frappe/database/database.py", line 786, in get_single_value
    ).run()
  File "apps/frappe/frappe/query_builder/utils.py", line 87, in execute_query
    result = frappe.db.sql(query, params, *args, **kwargs)  # nosemgrep
  File "apps/frappe/frappe/database/database.py", line 220, in sql
    self._cursor.execute(query, values)
  File "env/lib/python3.10/site-packages/pymysql/cursors.py", line 158, in execute
    result = self._query(query)
  File "env/lib/python3.10/site-packages/pymysql/cursors.py", line 325, in _query
    conn.query(q)
  File "env/lib/python3.10/site-packages/pymysql/connections.py", line 549, in query
    self._affected_rows = self._read_query_result(unbuffered=unbuffered)
  File "env/lib/python3.10/site-packages/pymysql/connections.py", line 779, in _read_query_result
    result.read()
  File "env/lib/python3.10/site-packages/pymysql/connections.py", line 1157, in read
    first_packet = self.connection._read_packet()
  File "env/lib/python3.10/site-packages/pymysql/connections.py", line 729, in _read_packet
    packet.raise_for_error()
  File "env/lib/python3.10/site-packages/pymysql/protocol.py", line 221, in raise_for_error
    err.raise_mysql_exception(self._data)
  File "env/lib/python3.10/site-packages/pymysql/err.py", line 143, in raise_mysql_exception
    raise errorclass(errno, errval)
pymysql.err.ProgrammingError: (1146, "Table '_1fb9db47a8d26d78.tabSingles' doesn't exist")

2024-01-10 17:05:56,107 ERROR scheduler Exception in Enqueue Events for Site NEW_INDIA
Traceback (most recent call last):
  File "apps/frappe/frappe/utils/scheduler.py", line 75, in enqueue_events_for_site
    if is_scheduler_inactive():
  File "apps/frappe/frappe/utils/scheduler.py", line 114, in is_scheduler_inactive
    if is_scheduler_disabled(verbose=verbose):
  File "apps/frappe/frappe/utils/scheduler.py", line 127, in is_scheduler_disabled
    frappe.db.get_single_value("System Settings", "enable_scheduler")
  File "apps/frappe/frappe/database/database.py", line 786, in get_single_value
    ).run()
  File "apps/frappe/frappe/query_builder/utils.py", line 87, in execute_query
    result = frappe.db.sql(query, params, *args, **kwargs)  # nosemgrep
  File "apps/frappe/frappe/database/database.py", line 220, in sql
    self._cursor.execute(query, values)
  File "env/lib/python3.10/site-packages/pymysql/cursors.py", line 158, in execute
    result = self._query(query)
  File "env/lib/python3.10/site-packages/pymysql/cursors.py", line 325, in _query
    conn.query(q)
  File "env/lib/python3.10/site-packages/pymysql/connections.py", line 549, in query
    self._affected_rows = self._read_query_result(unbuffered=unbuffered)
  File "env/lib/python3.10/site-packages/pymysql/connections.py", line 779, in _read_query_result
    result.read()
  File "env/lib/python3.10/site-packages/pymysql/connections.py", line 1157, in read
    first_packet = self.connection._read_packet()
  File "env/lib/python3.10/site-packages/pymysql/connections.py", line 729, in _read_packet
    packet.raise_for_error()
  File "env/lib/python3.10/site-packages/pymysql/protocol.py", line 221, in raise_for_error
    err.raise_mysql_exception(self._data)
  File "env/lib/python3.10/site-packages/pymysql/err.py", line 143, in raise_mysql_exception
    raise errorclass(errno, errval)
pymysql.err.ProgrammingError: (1146, "Table '_1fb9db47a8d26d78.tabSingles' doesn't exist")

2024-01-10 17:06:56,638 ERROR scheduler Exception in Enqueue Events for Site NEW_INDIA
Traceback (most recent call last):
  File "apps/frappe/frappe/utils/scheduler.py", line 75, in enqueue_events_for_site
    if is_scheduler_inactive():
  File "apps/frappe/frappe/utils/scheduler.py", line 114, in is_scheduler_inactive
    if is_scheduler_disabled(verbose=verbose):
  File "apps/frappe/frappe/utils/scheduler.py", line 127, in is_scheduler_disabled
    frappe.db.get_single_value("System Settings", "enable_scheduler")
  File "apps/frappe/frappe/database/database.py", line 786, in get_single_value
    ).run()
  File "apps/frappe/frappe/query_builder/utils.py", line 87, in execute_query
    result = frappe.db.sql(query, params, *args, **kwargs)  # nosemgrep
  File "apps/frappe/frappe/database/database.py", line 220, in sql
    self._cursor.execute(query, values)
  File "env/lib/python3.10/site-packages/pymysql/cursors.py", line 158, in execute
    result = self._query(query)
  File "env/lib/python3.10/site-packages/pymysql/cursors.py", line 325, in _query
    conn.query(q)
  File "env/lib/python3.10/site-packages/pymysql/connections.py", line 549, in query
    self._affected_rows = self._read_query_result(unbuffered=unbuffered)
  File "env/lib/python3.10/site-packages/pymysql/connections.py", line 779, in _read_query_result
    result.read()
  File "env/lib/python3.10/site-packages/pymysql/connections.py", line 1157, in read
    first_packet = self.connection._read_packet()
  File "env/lib/python3.10/site-packages/pymysql/connections.py", line 729, in _read_packet
    packet.raise_for_error()
  File "env/lib/python3.10/site-packages/pymysql/protocol.py", line 221, in raise_for_error
    err.raise_mysql_exception(self._data)
  File "env/lib/python3.10/site-packages/pymysql/err.py", line 143, in raise_mysql_exception
    raise errorclass(errno, errval)
pymysql.err.ProgrammingError: (1146, "Table '_1fb9db47a8d26d78.tabSingles' doesn't exist")

2024-01-10 17:07:57,076 ERROR scheduler Exception in Enqueue Events for Site NEW_INDIA
Traceback (most recent call last):
  File "apps/frappe/frappe/utils/scheduler.py", line 75, in enqueue_events_for_site
    if is_scheduler_inactive():
  File "apps/frappe/frappe/utils/scheduler.py", line 114, in is_scheduler_inactive
    if is_scheduler_disabled(verbose=verbose):
  File "apps/frappe/frappe/utils/scheduler.py", line 127, in is_scheduler_disabled
    frappe.db.get_single_value("System Settings", "enable_scheduler")
  File "apps/frappe/frappe/database/database.py", line 786, in get_single_value
    ).run()
  File "apps/frappe/frappe/query_builder/utils.py", line 87, in execute_query
    result = frappe.db.sql(query, params, *args, **kwargs)  # nosemgrep
  File "apps/frappe/frappe/database/database.py", line 220, in sql
    self._cursor.execute(query, values)
  File "env/lib/python3.10/site-packages/pymysql/cursors.py", line 158, in execute
    result = self._query(query)
  File "env/lib/python3.10/site-packages/pymysql/cursors.py", line 325, in _query
    conn.query(q)
  File "env/lib/python3.10/site-packages/pymysql/connections.py", line 549, in query
    self._affected_rows = self._read_query_result(unbuffered=unbuffered)
  File "env/lib/python3.10/site-packages/pymysql/connections.py", line 779, in _read_query_result
    result.read()
  File "env/lib/python3.10/site-packages/pymysql/connections.py", line 1157, in read
    first_packet = self.connection._read_packet()
  File "env/lib/python3.10/site-packages/pymysql/connections.py", line 729, in _read_packet
    packet.raise_for_error()
  File "env/lib/python3.10/site-packages/pymysql/protocol.py", line 221, in raise_for_error
    err.raise_mysql_exception(self._data)
  File "env/lib/python3.10/site-packages/pymysql/err.py", line 143, in raise_mysql_exception
    raise errorclass(errno, errval)
pymysql.err.ProgrammingError: (1146, "Table '_1fb9db47a8d26d78.tabSingles' doesn't exist")

